<robot name="onshape">
<link name="body+shoulder">
<visual>
<origin xyz="-0.058408271476315866411 -0.071223004110360185748 -0.0085368251527473404394" rpy="-2.9525394267533053564e-21 1.3821720341436699842e-06 -1.6864518502553366074e-15" />
<geometry>
<mesh filename="package:///body+shoulder.stl"/>
</geometry>
<material name="body+shoulder_material">
<color rgba="0.91764705882352937127 0.91764705882352937127 0.91764705882352937127 1.0"/>
</material>
</visual>
<collision>
<origin xyz="-0.058408271476315866411 -0.071223004110360185748 -0.0085368251527473404394" rpy="-2.9525394267533053564e-21 1.3821720341436699842e-06 -1.6864518502553366074e-15" />
<geometry>
<mesh filename="package:///body+shoulder.stl"/>
</geometry>
</collision>
<inertial>
<origin xyz="0.048497176920973890379 -0.069370712651254842762 0.17799151814900948665" rpy="0 0 0"/>
<mass value="3.8545932381461218696" />
<inertia ixx="0.060152765007805211739" ixy="3.3361997402525171042e-08"  ixz="3.3039220929823744386e-07" iyy="0.043858838042706453642" iyz="9.2445640495052863353e-08" izz="0.027316326908238916515" />
</inertial>
</link>

<link name="part_2">
<visual>
<origin xyz="-0.01040000000012818171 5.5511151231257827021e-17 -0.070000000000000006661" rpy="3.1415926535897922278 -3.4484967486265510788e-16 -2.9475207733788733206e-22" />
<geometry>
<mesh filename="package:///part_2.stl"/>
</geometry>
<material name="part_2_material">
<color rgba="0.64705882352941179736 0.64705882352941179736 0.64705882352941179736 1.0"/>
</material>
</visual>
<collision>
<origin xyz="-0.01040000000012818171 5.5511151231257827021e-17 -0.070000000000000006661" rpy="3.1415926535897922278 -3.4484967486265510788e-16 -2.9475207733788733206e-22" />
<geometry>
<mesh filename="package:///part_2.stl"/>
</geometry>
</collision>
<inertial>
<origin xyz="-0.0033381996615357658643 2.2269004441015492299e-06 -0.051519083111806432407" rpy="0 0 0"/>
<mass value="0.39331452861165566715" />
<inertia ixx="0.00052754286415478645039" ixy="-3.9952120601081768349e-08"  ixz="-6.7289354356839519651e-06" iyy="0.00050539176582950246126" iyz="-7.7152525403640223673e-08" izz="0.00026411189992770828716" />
</inertial>
</link>

<link name="part_3">
<visual>
<origin xyz="0 -7.8654853394656737341e-18 0.021599999999871503237" rpy="-1.570796326794896558 -1.570796326794896558 0" />
<geometry>
<mesh filename="package:///part_3.stl"/>
</geometry>
<material name="part_3_material">
<color rgba="0.61568627450980395466 0.81176470588235294379 0.92941176470588238168 1.0"/>
</material>
</visual>
<collision>
<origin xyz="0 -7.8654853394656737341e-18 0.021599999999871503237" rpy="-1.570796326794896558 -1.570796326794896558 0" />
<geometry>
<mesh filename="package:///part_3.stl"/>
</geometry>
</collision>
<inertial>
<origin xyz="-0.014848277604089269929 -4.7188965778669147621e-13 0.037296536893148664327" rpy="0 0 0"/>
<mass value="0.16190659177472260799" />
<inertia ixx="0.00018310319972791072227" ixy="-6.3351843220957550715e-16"  ixz="-1.3726888025232789108e-05" iyy="0.00024829283222596403285" iyz="-1.9974214181815416687e-15" izz="0.00017957233044235405665" />
</inertial>
</link>

<link name="part_4">
<visual>
<origin xyz="-0.010400000000128160893 -0.41399999999974551601 0.047000000000003094858" rpy="1.5707963267948961139 1.7969986971048004741e-19 0" />
<geometry>
<mesh filename="package:///part_4.stl"/>
</geometry>
<material name="part_4_material">
<color rgba="0.49803921568627451677 0.49803921568627451677 0.49803921568627451677 1.0"/>
</material>
</visual>
<collision>
<origin xyz="-0.010400000000128160893 -0.41399999999974551601 0.047000000000003094858" rpy="1.5707963267948961139 1.7969986971048004741e-19 0" />
<geometry>
<mesh filename="package:///part_4.stl"/>
</geometry>
</collision>
<inertial>
<origin xyz="-0.00027827049706477535729 1.6873243552262273681e-05 -0.10219808366514190889" rpy="0 0 0"/>
<mass value="0.54965419778071367141" />
<inertia ixx="0.0040057321582410232788" ixy="4.324141747539718652e-07"  ixz="-2.1760184829870909501e-05" iyy="0.0041665579747044347719" iyz="-1.2349165885809496772e-06" izz="0.00037323976031062086741" />
</inertial>
</link>

<link name="part_5">
<visual>
<origin xyz="0.28199033030083903162 -1.3767394800861065916e-15 -0.030410000000124164099" rpy="-1.570796326794896558 -1.5707963267948950037 0" />
<geometry>
<mesh filename="package:///part_5.stl"/>
</geometry>
<material name="part_5_material">
<color rgba="0.61568627450980395466 0.81176470588235294379 0.92941176470588238168 1.0"/>
</material>
</visual>
<collision>
<origin xyz="0.28199033030083903162 -1.3767394800861065916e-15 -0.030410000000124164099" rpy="-1.570796326794896558 -1.5707963267948950037 0" />
<geometry>
<mesh filename="package:///part_5.stl"/>
</geometry>
</collision>
<inertial>
<origin xyz="-0.015386110114917792013 7.0119387854280685614e-07 -0.022871083011768322812" rpy="0 0 0"/>
<mass value="0.14570208049488200808" />
<inertia ixx="0.0001287266127593706289" ixy="3.6900446662673844276e-09"  ixz="-1.2557254288043409823e-05" iyy="0.0001918944973627925688" iyz="-2.9320617881165657014e-10" izz="0.00015946298565579428695" />
</inertial>
</link>

<link name="part_6">
<visual>
<origin xyz="-0.010400000000125128596 1.0026892515504093417e-15 0.33099033030084007434" rpy="1.5707963267948952257 4.7811291522490992432e-16 -3.1554436208840472216e-30" />
<geometry>
<mesh filename="package:///part_6.stl"/>
</geometry>
<material name="part_6_material">
<color rgba="0.98039215686274505668 0.71372549019607844922 0.0039215686274509803377 1.0"/>
</material>
</visual>
<collision>
<origin xyz="-0.010400000000125128596 1.0026892515504093417e-15 0.33099033030084007434" rpy="1.5707963267948952257 4.7811291522490992432e-16 -3.1554436208840472216e-30" />
<geometry>
<mesh filename="package:///part_6.stl"/>
</geometry>
</collision>
<inertial>
<origin xyz="-0.0013213162768703401364 4.8154080758659200171e-05 -0.097602166863635098082" rpy="0 0 0"/>
<mass value="0.38335689533279360131" />
<inertia ixx="0.0020666255390986748748" ixy="-3.9655367094413866969e-07"  ixz="-5.1348233370063850673e-05" iyy="0.0021679442643270439676" iyz="5.9319691256864901749e-07" izz="0.00020735972322412333461" />
</inertial>
</link>

<link name="part_7">
<visual>
<origin xyz="0.53229033030084016431 -3.0316032632985517671e-16 0.020649999999874237705" rpy="-1.570796326794896558 -1.5707963267948943376 0" />
<geometry>
<mesh filename="package:///part_7.stl"/>
</geometry>
<material name="part_7_material">
<color rgba="0.49803921568627451677 0.49803921568627451677 0.49803921568627451677 1.0"/>
</material>
</visual>
<collision>
<origin xyz="0.53229033030084016431 -3.0316032632985517671e-16 0.020649999999874237705" rpy="-1.570796326794896558 -1.5707963267948943376 0" />
<geometry>
<mesh filename="package:///part_7.stl"/>
</geometry>
</collision>
<inertial>
<origin xyz="-0.022661581503697337397 1.9544908252598824156e-07 0.026783089489033500702" rpy="0 0 0"/>
<mass value="0.1273700598468369416" />
<inertia ixx="6.6482583031209958489e-05" ixy="-5.4023703048444017871e-10"  ixz="-2.5495988632889533438e-06" iyy="0.00013209260872466536854" iyz="6.4185164451621483522e-10" izz="0.00011552916294842997499" />
</inertial>
</link>

<joint name="part6-7" type="revolute">
<origin xyz="-0.031050000000000344685 -3.6507394443859324656e-17 -0.20130000000000003446" rpy="3.1415926535897908956 -1.5707963267948941155 0" />
<parent link="part_6" />
<child link="part_7" />
<axis xyz="0 0 1"/>
<limit effort="1" velocity="20" />
<joint_properties friction="0.0"/>
</joint>

<joint name="part5-6" type="revolute">
<origin xyz="-0.049000000000001001088 -8.0728878254443463311e-16 -0.020009999999998417941" rpy="-3.1415926535897904515 -1.5707963267948878983 0" />
<parent link="part_5" />
<child link="part_6" />
<axis xyz="0 0 1"/>
<limit effort="1" velocity="20" />
<joint_properties friction="0.0"/>
</joint>

<joint name="part4-5" type="revolute">
<origin xyz="0.020000000000000142664 -2.6577801743493259669e-16 -0.23499033030083990581" rpy="3.1415926535897922278 -1.5707963267948905628 0" />
<parent link="part_4" />
<child link="part_5" />
<axis xyz="0 0 1"/>
<limit effort="1" velocity="20" />
<joint_properties friction="0.0"/>
</joint>

<joint name="part3-4" type="revolute">
<origin xyz="-0.047000000000003733236 2.9804121513577497762e-16 0.032000000000000000666" rpy="3.141592653589793116 -1.5707963267948881203 0" />
<parent link="part_3" />
<child link="part_4" />
<axis xyz="0 0 1"/>
<limit effort="1" velocity="20" />
<joint_properties friction="0.0"/>
</joint>

<joint name="part2-3" type="revolute">
<origin xyz="-0.031999999999999688416 5.5511151231257827021e-17 -0.070000000000000034417" rpy="-1.570796326794896336 -2.8188842711213156842e-10 -1.5707963267948958919" />
<parent link="part_2" />
<child link="part_3" />
<axis xyz="0 0 1"/>
<limit effort="1" velocity="20" />
<joint_properties friction="0.0"/>
</joint>

<joint name="part1-2" type="revolute">
<origin xyz="0.048498297547935900753 -0.20587086960368033983 0.26789359987601968349" rpy="-1.5707963265130169273 1.382172033929337826e-06 -7.7506164438659163635e-16" />
<parent link="body+shoulder" />
<child link="part_2" />
<axis xyz="0 0 1"/>
<limit effort="1" velocity="20" />
<joint_properties friction="0.0"/>
</joint>

<link name="part_2-l">
<visual>
<origin xyz="-0.010400000000128202526 2.2204460492503130808e-16 -0.070000000000000020539" rpy="3.141592653589793116 3.9443045261050581512e-31 2.0302097146565415173e-22" />
<geometry>
<mesh filename="package:///part_2-l.stl"/>
</geometry>
<material name="part_2-l_material">
<color rgba="0.64705882352941179736 0.64705882352941179736 0.64705882352941179736 1.0"/>
</material>
</visual>
<collision>
<origin xyz="-0.010400000000128202526 2.2204460492503130808e-16 -0.070000000000000020539" rpy="3.141592653589793116 3.9443045261050581512e-31 2.0302097146565415173e-22" />
<geometry>
<mesh filename="package:///part_2-l.stl"/>
</geometry>
</collision>
<inertial>
<origin xyz="-0.00333820226862481962 2.2268674411764278205e-06 -0.051519081612306852347" rpy="0 0 0"/>
<mass value="0.39331447012894971138" />
<inertia ixx="0.00052754284663521623742" ixy="-3.9951912032262986419e-08"  ixz="-6.7289462771871816951e-06" iyy="0.0005053913292375718843" iyz="-7.7152612732443271037e-08" izz="0.00026411147134214536022" />
</inertial>
</link>

<link name="part_3-l">
<visual>
<origin xyz="0 -9.2642151609143688478e-18 0.021599999999871499767" rpy="-1.570796326794896558 -1.570796326794896558 0" />
<geometry>
<mesh filename="package:///part_3-l.stl"/>
</geometry>
<material name="part_3-l_material">
<color rgba="0.64705882352941179736 0.64705882352941179736 0.64705882352941179736 1.0"/>
</material>
</visual>
<collision>
<origin xyz="0 -9.2642151609143688478e-18 0.021599999999871499767" rpy="-1.570796326794896558 -1.570796326794896558 0" />
<geometry>
<mesh filename="package:///part_3-l.stl"/>
</geometry>
</collision>
<inertial>
<origin xyz="-0.014848277604088713083 -4.7183947539802103113e-13 0.037296536893148879432" rpy="0 0 0"/>
<mass value="0.16190659177472255248" />
<inertia ixx="0.00018310319972791145411" ixy="-6.3330376633288735906e-16"  ixz="-1.3726888025232778943e-05" iyy="0.00024829283222596560494" iyz="-1.9968953617425489853e-15" izz="0.00017957233044235638769" />
</inertial>
</link>

<link name="part_4-l">
<visual>
<origin xyz="-0.010400000000128202526 -0.41399999999974601561 0.047000000000002928324" rpy="1.570796326794896558 -3.1609582746478990436e-22 -1.9721522630525290756e-31" />
<geometry>
<mesh filename="package:///part_4-l.stl"/>
</geometry>
<material name="part_4-l_material">
<color rgba="0.49803921568627451677 0.49803921568627451677 0.49803921568627451677 1.0"/>
</material>
</visual>
<collision>
<origin xyz="-0.010400000000128202526 -0.41399999999974601561 0.047000000000002928324" rpy="1.570796326794896558 -3.1609582746478990436e-22 -1.9721522630525290756e-31" />
<geometry>
<mesh filename="package:///part_4-l.stl"/>
</geometry>
</collision>
<inertial>
<origin xyz="-0.0002782609471376536886 1.688684557737962777e-05 -0.10219805520733388216" rpy="0 0 0"/>
<mass value="0.54965439059867382543" />
<inertia ixx="0.0040057306991144875363" ixy="4.3250730698851595199e-07"  ixz="-2.1760161568327461215e-05" iyy="0.0041665562032017497765" iyz="-1.2340939371194491115e-06" izz="0.00037323935627230737325" />
</inertial>
</link>

<link name="part_5-l">
<visual>
<origin xyz="0.28199033030083897611 -1.3648321766915115799e-15 -0.030410000000124393083" rpy="-1.570796326794896558 -1.5707963267948941155 0" />
<geometry>
<mesh filename="package:///part_5-l.stl"/>
</geometry>
<material name="part_5-l_material">
<color rgba="0.2313725490196078538 0.38039215686274507888 0.7058823529411765163 1.0"/>
</material>
</visual>
<collision>
<origin xyz="0.28199033030083897611 -1.3648321766915115799e-15 -0.030410000000124393083" rpy="-1.570796326794896558 -1.5707963267948941155 0" />
<geometry>
<mesh filename="package:///part_5-l.stl"/>
</geometry>
</collision>
<inertial>
<origin xyz="-0.015386067341935464117 7.0141205334387691535e-07 -0.022871028924989270786" rpy="0 0 0"/>
<mass value="0.1457017362905156932" />
<inertia ixx="0.00012872642385460379981" ixy="3.6907328499586643491e-09"  ixz="-1.2557100546556266535e-05" iyy="0.00019189418076572261089" iyz="-2.9246209524147652749e-10" izz="0.00015946285676905831339" />
</inertial>
</link>

<link name="part_6-l">
<visual>
<origin xyz="-0.010400000000125302069 5.5992048032974084806e-16 0.33099033030084001883" rpy="1.570796326794896558 -1.5309338787605397866e-22 -1.9721522630525290756e-31" />
<geometry>
<mesh filename="package:///part_6-l.stl"/>
</geometry>
<material name="part_6-l_material">
<color rgba="0.97254901960784312376 0.52941176470588235947 0.0039215686274509803377 1.0"/>
</material>
</visual>
<collision>
<origin xyz="-0.010400000000125302069 5.5992048032974084806e-16 0.33099033030084001883" rpy="1.570796326794896558 -1.5309338787605397866e-22 -1.9721522630525290756e-31" />
<geometry>
<mesh filename="package:///part_6-l.stl"/>
</geometry>
</collision>
<inertial>
<origin xyz="-0.0013213097825716616646 4.8149291572077912915e-05 -0.097602169743160938076" rpy="0 0 0"/>
<mass value="0.38335734598388909733" />
<inertia ixx="0.0020666251420372789595" ixy="-3.9660305039552943691e-07"  ixz="-5.1348491952479231946e-05" iyy="0.0021679439006236029056" iyz="5.9342279586065842864e-07" izz="0.00020735979497207217108" />
</inertial>
</link>

<link name="part_7-l">
<visual>
<origin xyz="0.53229033030084016431 -4.479782044257553718e-16 0.020649999999875000983" rpy="-1.570796326794896558 -1.5707963267948925612 0" />
<geometry>
<mesh filename="package:///part_7-l.stl"/>
</geometry>
<material name="part_7-l_material">
<color rgba="0.64705882352941179736 0.64705882352941179736 0.64705882352941179736 1.0"/>
</material>
</visual>
<collision>
<origin xyz="0.53229033030084016431 -4.479782044257553718e-16 0.020649999999875000983" rpy="-1.570796326794896558 -1.5707963267948925612 0" />
<geometry>
<mesh filename="package:///part_7-l.stl"/>
</geometry>
</collision>
<inertial>
<origin xyz="-0.022661581569760169685 1.9544623432747415108e-07 0.026783089447952886097" rpy="0 0 0"/>
<mass value="0.12737006041498011299" />
<inertia ixx="6.648258316349044334e-05" ixy="-5.4024118909542238737e-10"  ixz="-2.5495989483425321918e-06" iyy="0.00013209260899370127429" iyz="6.4183554910985094211e-10" izz="0.00011552916310492705048" />
</inertial>
</link>

<joint name="part6-7_2" type="revolute">
<origin xyz="-0.031050000000000285705 2.4604350746546234826e-16 -0.20130000000000011773" rpy="3.1415926535897895633 -1.5707963267948934494 0" />
<parent link="part_6-l" />
<child link="part_7-l" />
<axis xyz="0 0 1"/>
<limit effort="1" velocity="20" />
<joint_properties friction="0.0"/>
</joint>

<joint name="part5-6_2" type="revolute">
<origin xyz="-0.049000000000001035783 -8.0132196852410703053e-16 -0.020009999999998397124" rpy="-3.141592653589793116 -1.5707963267948941155 0" />
<parent link="part_5-l" />
<child link="part_6-l" />
<axis xyz="0 0 1"/>
<limit effort="1" velocity="20" />
<joint_properties friction="0.0"/>
</joint>

<joint name="part4-5_2" type="revolute">
<origin xyz="0.02000000000000010103 -3.7796619267084454467e-17 -0.23499033030084018336" rpy="3.141592653589793116 -1.570796326794896558 0" />
<parent link="part_4-l" />
<child link="part_5-l" />
<axis xyz="0 0 1"/>
<limit effort="1" velocity="20" />
<joint_properties friction="0.0"/>
</joint>

<joint name="part3-4_2" type="revolute">
<origin xyz="-0.047000000000003677725 2.3991707719535512709e-16 0.032000000000000007605" rpy="3.141592653589793116 -1.5707963267948927832 0" />
<parent link="part_3-l" />
<child link="part_4-l" />
<axis xyz="0 0 1"/>
<limit effort="1" velocity="20" />
<joint_properties friction="0.0"/>
</joint>

<joint name="part2-3_2" type="revolute">
<origin xyz="-0.031999999999999667599 1.6653345369377348106e-16 -0.07000000000000007605" rpy="1.570796326794896558 2.8187950903072009954e-10 1.5707963267948990005" />
<parent link="part_2-l" />
<child link="part_3-l" />
<axis xyz="0 0 1"/>
<limit effort="1" velocity="20" />
<joint_properties friction="0.0"/>
</joint>

<joint name="part1-2_2" type="revolute">
<origin xyz="0.048498297547936462804 0.067129130396311978424 0.26789359995297473693" rpy="1.570796327076777299 1.3821720341436699842e-06 -2.2121474781181312146e-15" />
<parent link="body+shoulder" />
<child link="part_2-l" />
<axis xyz="0 0 1"/>
<limit effort="1" velocity="20" />
<joint_properties friction="0.0"/>
</joint>


</robot>
